#YamlMime:PythonReference
api_name: []
items:
- _type: class
  children: []
  class: azure.servicefabric.models.TestErrorChaosEvent
  fullName: azure.servicefabric.models.TestErrorChaosEvent
  inheritance:
  - inheritance:
    - inheritance:
      - type: builtins.object
      type: msrest.serialization.Model
    type: azure.servicefabric.models.chaos_event.ChaosEvent
  langs:
  - python
  module: azure.servicefabric.models
  name: TestErrorChaosEvent
  source:
    id: TestErrorChaosEvent
    path: \azure_servicefabric-5.6.130-py3.5.egg\azure\servicefabric\models\test_error_chaos_event.py
    remote:
      branch: master
      path: \azure_servicefabric-5.6.130-py3.5.egg\azure\servicefabric\models\test_error_chaos_event.py
      repo: https://github.com/swatDong/azure-sdk-for-python
    startLine: 15
  summary: 'Bases: `azure.servicefabric.models.chaos_event.ChaosEvent`

    Describes a Chaos event that gets generated when an unexpected event occurs in
    the Chaos engine. For example, due to the cluster snapshot being inconsistent,
    while faulting a faultable entity, Chaos found that the entity was alreay faulted
    -- which would be an unexpected event. .'
  syntax:
    content: TestErrorChaosEvent(self, time_stamp_utc, reason=None)
    parameters:
    - description: ''
      id: time_stamp_utc
      type:
      - datetime
    - description: Polymorphic Discriminator
      id: Kind
      type:
      - str
    - description: ''
      id: reason
      type:
      - str
  type: Class
  uid: azure.servicefabric.models.TestErrorChaosEvent
references: []
